<?xml version="1.0"?>
<robot name="mainbot" xmlns:xacro="http://ros.org/wiki/xacro">

	<xacro:include filename="$(find project)/urdf/common_properties.xacro"/>
	<xacro:include filename="$(find project)/urdf/mainbot.gazebo.xacro"/>

	<xacro:macro name="visual1" params="length radius color">
                <visual>
                        <geometry>
                                <cylinder length="${length}" radius="${radius}"/>
                        </geometry>
                        <material name="${color}"/>
                </visual>
                <collision>
                        <geometry>
                                <cylinder length="${length}" radius="${radius}"/>
                        </geometry>
                </collision>
        </xacro:macro>

        <xacro:macro name="visual2" params="length width height color">
                <visual>
                        <geometry>
                                <box size="${length} ${width} ${height}"/>
                        </geometry>
                        <material name="${color}"/>
                </visual>
                <collision>
                        <geometry>
                                <box size="${length} ${width} ${height}"/>
                        </geometry>
                </collision>
        </xacro:macro>
	
        <xacro:macro name="inertial_" params="mass">
                <inertial>
                        <mass value="${mass}"/>
                        <inertia ixx="1.0" ixy="0.0" ixz="0.0" iyy="1.0" iyz="0.0" izz="1.0" />
                </inertial>
        </xacro:macro>

	<link name="base_footprint"/>
	<joint name="fixed" type="fixed">
		<parent link="base_footprint"/>
		<child link="link1"/>
		<origin rpy="0 0 ${pi/2}"/>
	</joint>

	<link name="link1">
		<xacro:visual2 length="0.5" width="0.5" height="0.05" color="grey"/>
		<xacro:inertial_ mass="1"/>
	</link>

	<link name="right_wall">
		<xacro:visual2 length="0.05" width="0.4" height="0.5" color="grey"/>
		<xacro:inertial_ mass="1"/>
	</link>
	
	<joint name="right_wall_joint" type="fixed">
		<parent link="link1"/>
		<child link="right_wall"/>
		<origin xyz="0.225 0 0.275"/>
	</joint>

	<link name="left_wall">
		<xacro:visual2 length="0.05" width="0.4" height="0.5" color="grey"/>
		<xacro:inertial_ mass="1"/>
	</link>
	
	<joint name="left_wall_joint" type="fixed">
		<parent link="link1"/>
		<child link="left_wall"/>
		<origin xyz="-0.225 0 0.275"/>
	</joint>
	
	<link name="front_wall">
		<xacro:visual2 length="0.5" width="0.05" height="0.5" color="grey"/>
		<xacro:inertial_ mass="1"/>
	</link>
	
	<joint name="front_wall_joint" type="fixed">
		<parent link="link1"/>
		<child link="front_wall"/>
		<origin xyz="0 0.225 0.275"/>
	</joint>
	
	<link name="back_wall">
		<xacro:visual2 length="0.5" width="0.05" height="0.5" color="grey"/>
		<xacro:inertial_ mass="1"/>
	</link>
	
	<joint name="back_wall_joint" type="fixed">
		<parent link="link1"/>
		<child link="back_wall"/>
		<origin xyz="0 -0.225 0.275"/>
	</joint>
	
	<!--<link name="main_board">
		<xacro:visual2 length="0.5" width="0.2" height="0.5" color="white"/>
		<xacro:inertial_ mass="3"/>
	</link>
	
	<joint name="main_board_joint" type="fixed">
		<parent link="back_wall"/>
		<child link="main_board"/>
		<origin xyz="0 0.575 0"/>
	</joint> -->

	<link name="front_right_wheel">
		<xacro:visual1 length="0.15" radius="0.15" color="black"/>
		<inertial>
			<mass value="2.8498940e-02" />
			<inertia ixx="1.1175580e-05" ixy="-4.2369783e-11" ixz="-5.9381719e-09" iyy="1.1192413e-05" iyz="-1.4400107e-11" izz="2.0712558e-05" />
		</inertial>

	</link>

	<joint name="front_right_wheel_joint" type="continuous">
		<parent link="link1"/>
                <child link="front_right_wheel"/>
		<origin xyz="0.325 0.2 0" rpy="0 ${pi/2} 0"/>
                <axis xyz="0 0 1"/>
	</joint>
	
	<link name="back_right_wheel">
		<xacro:visual1 length="0.15" radius="0.15" color="black"/>
		<inertial>
			<mass value="2.8498940e-02" />
			<inertia ixx="1.1175580e-05" ixy="-4.2369783e-11" ixz="-5.9381719e-09" iyy="1.1192413e-05" iyz="-1.4400107e-11" izz="2.0712558e-05" />
		</inertial>
	</link>

	<joint name="back_right_wheel_joint" type="continuous">
		<parent link="link1"/>
                <child link="back_right_wheel"/>
		<origin xyz="0.325 -0.2 0" rpy="0 ${pi/2} 0"/>
		<axis xyz="0 0 1"/>
	</joint>

	<link name="front_left_wheel">
		<xacro:visual1 length="0.15" radius="0.15" color="black"/>
		<inertial>
			<mass value="2.8498940e-02" />
			<inertia ixx="1.1175580e-05" ixy="-4.2369783e-11" ixz="-5.9381719e-09" iyy="1.1192413e-05" iyz="-1.4400107e-11" izz="2.0712558e-05" />
		</inertial>
	</link>

	<joint name="front_left_wheel_joint" type="continuous">
		<parent link="link1"/>
                <child link="front_left_wheel"/>
		<origin xyz="-0.325 0.2 0" rpy="0 ${pi/2} 0"/>
                <axis xyz="0 0 1"/>
	</joint>
	
	<link name="back_left_wheel">
		<xacro:visual1 length="0.15" radius="0.15" color="black"/>
		<inertial>
			<mass value="2.8498940e-02" />
			<inertia ixx="1.1175580e-05" ixy="-4.2369783e-11" ixz="-5.9381719e-09" iyy="1.1192413e-05" iyz="-1.4400107e-11" izz="2.0712558e-05" />
		</inertial>
	</link>

	<joint name="back_left_wheel_joint" type="continuous">
		<parent link="link1"/>
                <child link="back_left_wheel"/>
		<origin xyz="-0.325 -0.2 0" rpy="0 ${pi/2} 0"/>
                <axis xyz="0 0 1"/>
	</joint>

	<link name="laser_scan">
		<xacro:visual2 length="0.05" width="0.05" height="0.05" color="red"/>
		<xacro:inertial_ mass="0.01"/>
	</link>
	
	<joint name="laser_joint" type="fixed">
		<parent link="front_wall"/>
		<child link="laser_scan"/>
		<origin xyz="0 -0.45 0.275"/>
	</joint>
	
	<link name="imu_link"/>
	
	<joint name="imu_joint" type="fixed">
		<parent link="link1"/>
		<child link="imu_link"/>
		<origin xyz="0 0 0.025" rpy="0 0 0"/>
	</joint>


</robot>
